Workbook

Sheet 運動
A1: 日期 | B1: 周 | C1: 運動項目 | N1: 訓練量 | P1: 每日活動量 | R1: 總評分 | V1: 週數
C2: 力量 | L2: 有氧 | N2: 力量 | O2: 有氧 | V2: =COUNT(B9:B99999) -> 59
A3: 單位 | C3: KG | D3: 下 | E3: 下 | F3: 下 | G3: 下 | H3: 下 | I3: 下 | J3: 秒 | K3: 秒 | L3: KM | M3: KM | N3: KG | O3: KM | Q3: 步數
A4: 每單位訓練量(換算KG) | C4: 1 | D4: 60 | E4: 45 | F4: 40 | G4: 50 | H4: 5 | I4: 45 | J4: 5 | K4: 5 | L4: 1 | M4: 2.5 | N4: 1 | O4: 1000 | Q4: 0.2
A5: 生涯總和 | C5: 重訓台 | D5: 重訓器材 | E5: 反向划船 | F5: 伏地起身 | G5: 弓步蹲 | H5: 開合跳 | I5: 啞鈴深蹲 | J5: 捲腹 | K5: 超人式 | L5: 跑步機 | M5: 跑步機負重 | N5: 力量 | O5: 有氧 | P5: 平均 | Q5: 總步數 | R5: 力量 | S5: 有氧 | T5: 活動量 | U5: 總評分
C6: =SUM(C9:C10006) -> 113465 | D6: =SUM(D9:D10006) -> 620 | E6: =SUM(E9:E10006) -> 283 | F6: =SUM(F9:F10006) -> 1274 | G6: =SUM(G9:G10006) -> 991 | H6: =SUM(H9:H10006) -> 8940 | I6: =SUM(I9:I10006) -> 1329 | J6: =SUM(J9:J10006) -> 4364 | ... O6: =SUM(O9:O10006) -> 411.945 | P6: =AVERAGE(P9:P10006) -> 4306.5085 | Q6: =AVERAGE(Q9:Q10006) -> 30145.559 | R6: =SUM(R9:R10006) -> 403735 | S6: =SUM(S9:S10006) -> 411945 | T6: =SUM(T9:T10006) -> 355717.6 | U6: =SUM(U9:U10006) -> 1171397.6
C7: =AVERAGE(C9:C9999) -> 1923.1356 | D7: =AVERAGE(D9:D9999) -> 10.508475 | E7: =AVERAGE(E9:E9999) -> 6.5813953 | F7: =AVERAGE(F9:F9999) -> 21.59322 | G7: =AVERAGE(G9:G9999) -> 16.79661 | H7: =AVERAGE(H9:H9999) -> 151.52542 | I7: =AVERAGE(I9:I9999) -> 22.525424 | J7: =AVERAGE(J9:J9999) -> 73.966102 | ... O7: =AVERAGE(O9:O9999) -> 6.9821186 | R7: =AVERAGE(R9:R9999) -> 6842.9661 | S7: =AVERAGE(S9:S9999) -> 6982.1186 | T7: =AVERAGE(T9:T9999) -> 6029.1119 | U7: =AVERAGE(U9:U9999) -> 19854.197
B8: 周 | C8: 重訓台 | D8: 重訓器材 | E8: 反向划船 | F8: 伏地起身 | G8: 弓步蹲 | H8: 開合跳 | I8: 啞鈴深蹲 | J8: 捲腹 | K8: 超人式 | L8: 跑步機 | M8: 跑步機負重 | N8: 力量 | O8: 有氧 | P8: 平均 | Q8: 總步數 | R8: 力量 | S8: 有氧 | T8: 活動量 | U8: 總評分 | V8: 力量排名 | W8: 有氧排名 | X8: 活動量排名 | Y8: 總排名 | Z8: 前幾%
A9: 45543 | B9: 1 | C9: 3500 | D9: 5 | F9: 10 | G9: 10 | H9: 160 | I9: 13 | J9: 0 | L9: 5.15 | M9: 0.81 | N9: =C9*$C$4+D9*$D$4+E9*$E$4+F9*$F$4+G9*$G$4+H9*$H$4+I9*$I$4+J9*$J$4 -> 6085 | O9: =L9*$L$4+M9*$M$4 -> 7.175 | P9: 4260 | Q9: =P9*7 -> 29820 | R9: =N9*$N$4 -> 6085 | S9: =O9*$O$4 -> 7175 | T9: =Q9*$Q$4 -> 5964 | U9: =SUM(R9:T9) -> 19224 | V9: =RANK(R9,$R$9:$R$10002) -> 36 | W9: =RANK(S9,$S$9:$S$10002) -> 24 | X9: =RANK(T9,$T$9:$T$10002) -> 28 | Y9: =RANK(U9,$U$9:$U$10002) -> 31 | Z9: =_xlfn.CONCAT(ROUND((1-PERCENTRANK($U$9:$U$10002,U9,2))*100,2),"%") -> 52%
A10: 45550 | B10: 2 | C10: 1700 | D10: 7 | F10: 10 | G10: 16 | H10: 160 | I10: 16 | J10: 0 | L10: 5.01 | M10: 0.84 | N10: =C10*$C$4+D10*$D$4+E10*$E$4+F10*$F$4+G10*$G$4+H10*$H$4+I10*$I$4+J10*$J$4 -> 4840 | O10: =L10*$L$4+M10*$M$4 -> 7.11 | P10: 3151 | Q10: =P10*7 -> 22057 | R10: =N10*$N$4 -> 4840 | S10: =O10*$O$4 -> 7110 | T10: =Q10*$Q$4 -> 4411.4 | U10: =SUM(R10:T10) -> 16361.4 | V10: =RANK(R10,$R$9:$R$10002) -> 46 | W10: =RANK(S10,$S$9:$S$10002) -> 26 | X10: =RANK(T10,$T$9:$T$10002) -> 47 | Y10: =RANK(U10,$U$9:$U$10002) -> 48 | Z10: =_xlfn.CONCAT(ROUND((1-PERCENTRANK($U$9:$U$10002,U10,2))*100,2),"%") -> 82%
A11: 45557 | B11: 3 | C11: 0 | D11: 0 | F11: 85 | G11: 56 | H11: 540 | I11: 0 | J11: 114 | L11: 5.15 | M11: 0 | N11: =C11*$C$4+D11*$D$4+E11*$E$4+F11*$F$4+G11*$G$4+H11*$H$4+I11*$I$4+J11*$J$4 -> 9470 | O11: =L11*$L$4+M11*$M$4 -> 5.15 | P11: 5733 | Q11: =P11*7 -> 40131 | R11: =N11*$N$4 -> 9470 | S11: =O11*$O$4 -> 5150 | T11: =Q11*$Q$4 -> 8026.2 | U11: =SUM(R11:T11) -> 22646.2 | V11: =RANK(R11,$R$9:$R$10002) -> 9 | W11: =RANK(S11,$S$9:$S$10002) -> 44 | X11: =RANK(T11,$T$9:$T$10002) -> 9 | Y11: =RANK(U11,$U$9:$U$10002) -> 15 | Z11: =_xlfn.CONCAT(ROUND((1-PERCENTRANK($U$9:$U$10002,U11,2))*100,2),"%") -> 25%
A12: 45564 | B12: 4 | C12: 2400 | D12: 12 | F12: 45 | G12: 27 | H12: 300 | I12: 30 | J12: 115 | L12: 5.22 | M12: 0.93 | N12: =C12*$C$4+D12*$D$4+E12*$E$4+F12*$F$4+G12*$G$4+H12*$H$4+I12*$I$4+J12*$J$4 -> 9695 | O12: =L12*$L$4+M12*$M$4 -> 7.545 | P12: 2629 | Q12: =P12*7 -> 18403 | R12: =N12*$N$4 -> 9695 | S12: =O12*$O$4 -> 7545 | T12: =Q12*$Q$4 -> 3680.6 | U12: =SUM(R12:T12) -> 20920.6 | V12: =RANK(R12,$R$9:$R$10002) -> 7 | W12: =RANK(S12,$S$9:$S$10002) -> 23 | X12: =RANK(T12,$T$9:$T$10002) -> 55 | Y12: =RANK(U12,$U$9:$U$10002) -> 24 | Z12: =_xlfn.CONCAT(ROUND((1-PERCENTRANK($U$9:$U$10002,U12,2))*100,2),"%") -> 40%
A13: 45571 | B13: 5 | C13: 1600 | D13: 12 | F13: 30 | G13: 30 | H13: 250 | I13: 30 | J13: 110 | L13: 4.6 | M13: 1 | N13: =C13*$C$4+D13*$D$4+E13*$E$4+F13*$F$4+G13*$G$4+H13*$H$4+I13*$I$4+J13*$J$4 -> 8170 | O13: =L13*$L$4+M13*$M$4 -> 7.1 | P13: 2415 | Q13: =P13*7 -> 16905 | R13: =N13*$N$4 -> 8170 | S13: =O13*$O$4 -> 7100 | T13: =Q13*$Q$4 -> 3381 | U13: =SUM(R13:T13) -> 18651 | V13: =RANK(R13,$R$9:$R$10002) -> 18 | W13: =RANK(S13,$S$9:$S$10002) -> 27 | X13: =RANK(T13,$T$9:$T$10002) -> 58 | Y13: =RANK(U13,$U$9:$U$10002) -> 34 | Z13: =_xlfn.CONCAT(ROUND((1-PERCENTRANK($U$9:$U$10002,U13,2))*100,2),"%") -> 57%
A14: 45578 | B14: 6 | C14: 2800 | D14: 16 | F14: 20 | G14: 20 | H14: 200 | I14: 35 | J14: 245 | L14: 0 | M14: 0.88 | N14: =C14*$C$4+D14*$D$4+E14*$E$4+F14*$F$4+G14*$G$4+H14*$H$4+I14*$I$4+J14*$J$4 -> 9360 | O14: =L14*$L$4+M14*$M$4 -> 2.2 | P14: 3374 | Q14: =P14*7 -> 23618 | R14: =N14*$N$4 -> 9360 | S14: =O14*$O$4 -> 2200 | T14: =Q14*$Q$4 -> 4723.6 | U14: =SUM(R14:T14) -> 16283.6 | V14: =RANK(R14,$R$9:$R$10002) -> 11 | W14: =RANK(S14,$S$9:$S$10002) -> 57 | X14: =RANK(T14,$T$9:$T$10002) -> 43 | Y14: =RANK(U14,$U$9:$U$10002) -> 49 | Z14: =_xlfn.CONCAT(ROUND((1-PERCENTRANK($U$9:$U$10002,U14,2))*100,2),"%") -> 83%
A15: 45585 | B15: 7 | C15: 2800 | D15: 7 | F15: 12 | G15: 20 | H15: 100 | I15: 32 | J15: 60 | L15: 4.5 | M15: 0.86 | N15: =C15*$C$4+D15*$D$4+E15*$E$4+F15*$F$4+G15*$G$4+H15*$H$4+I15*$I$4+J15*$J$4 -> 6940 | O15: =L15*$L$4+M15*$M$4 -> 6.65 | P15: 4021 | Q15: =P15*7 -> 28147 | R15: =N15*$N$4 -> 6940 | S15: =O15*$O$4 -> 6650 | T15: =Q15*$Q$4 -> 5629.4 | U15: =SUM(R15:T15) -> 19219.4 | V15: =RANK(R15,$R$9:$R$10002) -> 31 | W15: =RANK(S15,$S$9:$S$10002) -> 28 | X15: =RANK(T15,$T$9:$T$10002) -> 33 | Y15: =RANK(U15,$U$9:$U$10002) -> 32 | Z15: =_xlfn.CONCAT(ROUND((1-PERCENTRANK($U$9:$U$10002,U15,2))*100,2),"%") -> 54%
A16: 45592 | B16: 8 | C16: 2000 | D16: 18 | F16: 10 | G16: 20 | H16: 100 | I16: 33 | J16: 110 | L16: 3 | M16: 1 | N16: =C16*$C$4+D16*$D$4+E16*$E$4+F16*$F$4+G16*$G$4+H16*$H$4+I16*$I$4+J16*$J$4 -> 7015 | O16: =L16*$L$4+M16*$M$4 -> 5.5 | P16: 2460 | Q16: =P16*7 -> 17220 | R16: =N16*$N$4 -> 7015 | S16: =O16*$O$4 -> 5500 | T16: =Q16*$Q$4 -> 3444 | U16: =SUM(R16:T16) -> 15959 | V16: =RANK(R16,$R$9:$R$10002) -> 30 | W16: =RANK(S16,$S$9:$S$10002) -> 40 | X16: =RANK(T16,$T$9:$T$10002) -> 57 | Y16: =RANK(U16,$U$9:$U$10002) -> 50 | Z16: =_xlfn.CONCAT(ROUND((1-PERCENTRANK($U$9:$U$10002,U16,2))*100,2),"%") -> 85%
A17: 45599 | B17: 9 | C17: 2200 | D17: 11 | F17: 38 | G17: 30 | H17: 270 | I17: 12 | J17: 60 | L17: 3 | M17: 1.1 | N17: =C17*$C$4+D17*$D$4+E17*$E$4+F17*$F$4+G17*$G$4+H17*$H$4+I17*$I$4+J17*$J$4 -> 8070 | O17: =L17*$L$4+M17*$M$4 -> 5.75 | P17: 2587 | Q17: =P17*7 -> 18109 | R17: =N17*$N$4 -> 8070 | S17: =O17*$O$4 -> 5750 | T17: =Q17*$Q$4 -> 3621.8 | U17: =SUM(R17:T17) -> 17441.8 | V17: =RANK(R17,$R$9:$R$10002) -> 19 | W17: =RANK(S17,$S$9:$S$10002) -> 34 | X17: =RANK(T17,$T$9:$T$10002) -> 56 | Y17: =RANK(U17,$U$9:$U$10002) -> 43 | Z17: =_xlfn.CONCAT(ROUND((1-PERCENTRANK($U$9:$U$10002,U17,2))*100,2),"%") -> 73%
A18: 45606 | B18: 10 | C18: 1200 | D18: 0 | F18: 20 | G18: 10 | H18: 100 | I18: 22 | J18: 75 | L18: 0 | M18: 1.2 | N18: =C18*$C$4+D18*$D$4+E18*$E$4+F18*$F$4+G18*$G$4+H18*$H$4+I18*$I$4+J18*$J$4 -> 4365 | O18: =L18*$L$4+M18*$M$4 -> 3 | P18: 3431 | Q18: =P18*7 -> 24017 | R18: =N18*$N$4 -> 4365 | S18: =O18*$O$4 -> 3000 | T18: =Q18*$Q$4 -> 4803.4 | U18: =SUM(R18:T18) -> 12168.4 | V18: =RANK(R18,$R$9:$R$10002) -> 50 | W18: =RANK(S18,$S$9:$S$10002) -> 54 | X18: =RANK(T18,$T$9:$T$10002) -> 42 | Y18: =RANK(U18,$U$9:$U$10002) -> 58 | Z18: =_xlfn.CONCAT(ROUND((1-PERCENTRANK($U$9:$U$10002,U18,2))*100,2),"%") -> 99%
A19: 45613 | B19: 11 | C19: 2000 | D19: 7 | F19: 30 | G19: 30 | H19: 250 | I19: 33 | J19: 135 | L19: 2.69 | M19: 1.14 | N19: =C19*$C$4+D19*$D$4+E19*$E$4+F19*$F$4+G19*$G$4+H19*$H$4+I19*$I$4+J19*$J$4 -> 8530 | O19: =L19*$L$4+M19*$M$4 -> 5.54 | P19: 3966 | Q19: =P19*7 -> 27762 | R19: =N19*$N$4 -> 8530 | S19: =O19*$O$4 -> 5540 | T19: =Q19*$Q$4 -> 5552.4 | U19: =SUM(R19:T19) -> 19622.4 | V19: =RANK(R19,$R$9:$R$10002) -> 17 | W19: =RANK(S19,$S$9:$S$10002) -> 38 | X19: =RANK(T19,$T$9:$T$10002) -> 34 | Y19: =RANK(U19,$U$9:$U$10002) -> 28 | Z19: =_xlfn.CONCAT(ROUND((1-PERCENTRANK($U$9:$U$10002,U19,2))*100,2),"%") -> 47%
A20: 45620 | B20: 12 | C20: 1500 | D20: 14 | F20: 22 | G20: 20 | H20: 100 | I20: 33 | J20: 120 | L20: 3 | M20: 0.87 | N20: =C20*$C$4+D20*$D$4+E20*$E$4+F20*$F$4+G20*$G$4+H20*$H$4+I20*$I$4+J20*$J$4 -> 6805 | O20: =L20*$L$4+M20*$M$4 -> 5.175 | P20: 2772 | Q20: =P20*7 -> 19404 | R20: =N20*$N$4 -> 6805 | S20: =O20*$O$4 -> 5175 | T20: =Q20*$Q$4 -> 3880.8 | U20: =SUM(R20:T20) -> 15860.8 | V20: =RANK(R20,$R$9:$R$10002) -> 32 | W20: =RANK(S20,$S$9:$S$10002) -> 43 | X20: =RANK(T20,$T$9:$T$10002) -> 51 | Y20: =RANK(U20,$U$9:$U$10002) -> 52 | Z20: =_xlfn.CONCAT(ROUND((1-PERCENTRANK($U$9:$U$10002,U20,2))*100,2),"%") -> 88%
... A24: 45648 | B24: 16 | C24: 3100 | D24: 12 | F24: 20 | G24: 20 | H24: 150 | I24: 22 | J24: 0 | L24: 1.49 | M24: 1.77 | N24: =C24*$C$4+D24*$D$4+E24*$E$4+F24*$F$4+G24*$G$4+H24*$H$4+I24*$I$4+J24*$J$4 -> 7360 | O24: =L24*$L$4+M24*$M$4 -> 5.915 | P24: 5607 | Q24: =P24*7 -> 39249 | R24: =N24*$N$4 -> 7360 | S24: =O24*$O$4 -> 5915 | T24: =Q24*$Q$4 -> 7849.8 | U24: =SUM(R24:T24) -> 21124.8 | V24: =RANK(R24,$R$9:$R$10002) -> 27 | W24: =RANK(S24,$S$9:$S$10002) -> 33 | X24: =RANK(T24,$T$9:$T$10002) -> 10 | Y24: =RANK(U24,$U$9:$U$10002) -> 23 | Z24: =_xlfn.CONCAT(ROUND((1-PERCENTRANK($U$9:$U$10002,U24,2))*100,2),"%") -> 38%
A25: 45655 | B25: 17 | C25: 2300 | D25: 15 | E25: 15 | F25: 40 | G25: 30 | H25: 250 | I25: 40 | J25: 120 | L25: 1.33 | M25: 1.86 | N25: =C25*$C$4+D25*$D$4+E25*$E$4+F25*$F$4+G25*$G$4+H25*$H$4+I25*$I$4+J25*$J$4 -> 10625 | O25: =L25*$L$4+M25*$M$4 -> 5.98 | P25: 5221 | Q25: =P25*7 -> 36547 | R25: =N25*$N$4 -> 10625 | S25: =O25*$O$4 -> 5980 | T25: =Q25*$Q$4 -> 7309.4 | U25: =SUM(R25:T25) -> 23914.4 | V25: =RANK(R25,$R$9:$R$10002) -> 3 | W25: =RANK(S25,$S$9:$S$10002) -> 32 | X25: =RANK(T25,$T$9:$T$10002) -> 13 | Y25: =RANK(U25,$U$9:$U$10002) -> 8 | Z25: =_xlfn.CONCAT(ROUND((1-PERCENTRANK($U$9:$U$10002,U25,2))*100,2),"%") -> 13%
A26: 45662 | B26: 18 | C26: 2700 | D26: 14 | E26: 6 | F26: 45 | G26: 30 | H26: 220 | I26: 44 | J26: 120 | L26: 3.1 | M26: 2 | N26: =C26*$C$4+D26*$D$4+E26*$E$4+F26*$F$4+G26*$G$4+H26*$H$4+I26*$I$4+J26*$J$4 -> 10790 | O26: =L26*$L$4+M26*$M$4 -> 8.1 | P26: 4384 | Q26: =P26*7 -> 30688 | R26: =N26*$N$4 -> 10790 | S26: =O26*$O$4 -> 8100 | T26: =Q26*$Q$4 -> 6137.6 | U26: =SUM(R26:T26) -> 25027.6 | V26: =RANK(R26,$R$9:$R$10002) -> 2 | W26: =RANK(S26,$S$9:$S$10002) -> 20 | X26: =RANK(T26,$T$9:$T$10002) -> 23 | Y26: =RANK(U26,$U$9:$U$10002) -> 5 | Z26: =_xlfn.CONCAT(ROUND((1-PERCENTRANK($U$9:$U$10002,U26,2))*100,2),"%") -> 7%
A27: 45669 | B27: 19 | C27: 3000 | D27: 22 | E27: 10 | F27: 20 | G27: 15 | H27: 200 | I27: 20 | J27: 100 | L27: 3 | M27: 2.1 | N27: =C27*$C$4+D27*$D$4+E27*$E$4+F27*$F$4+G27*$G$4+H27*$H$4+I27*$I$4+J27*$J$4 -> 8720 | O27: =L27*$L$4+M27*$M$4 -> 8.25 | P27: 3614 | Q27: =P27*7 -> 25298 | R27: =N27*$N$4 -> 8720 | S27: =O27*$O$4 -> 8250 | T27: =Q27*$Q$4 -> 5059.6 | U27: =SUM(R27:T27) -> 22029.6 | V27: =RANK(R27,$R$9:$R$10002) -> 14 | W27: =RANK(S27,$S$9:$S$10002) -> 18 | X27: =RANK(T27,$T$9:$T$10002) -> 40 | Y27: =RANK(U27,$U$9:$U$10002) -> 18 | Z27: =_xlfn.CONCAT(ROUND((1-PERCENTRANK($U$9:$U$10002,U27,2))*100,2),"%") -> 30%
A28: 45676 | B28: 20 | C28: 3100 | D28: 13 | E28: 11 | F28: 30 | G28: 15 | H28: 250 | I28: 42 | J28: 75 | L28: 2.71 | M28: 2.2 | N28: =C28*$C$4+D28*$D$4+E28*$E$4+F28*$F$4+G28*$G$4+H28*$H$4+I28*$I$4+J28*$J$4 -> 9840 | O28: =L28*$L$4+M28*$M$4 -> 8.21 | P28: 6519 | Q28: =P28*7 -> 45633 | R28: =N28*$N$4 -> 9840 | S28: =O28*$O$4 -> 8210 | T28: =Q28*$Q$4 -> 9126.6 | U28: =SUM(R28:T28) -> 27176.6 | V28: =RANK(R28,$R$9:$R$10002) -> 6 | W28: =RANK(S28,$S$9:$S$10002) -> 19 | X28: =RANK(T28,$T$9:$T$10002) -> 5 | Y28: =RANK(U28,$U$9:$U$10002) -> 3 | Z28: =_xlfn.CONCAT(ROUND((1-PERCENTRANK($U$9:$U$10002,U28,2))*100,2),"%") -> 4%
A29: 45683 | B29: 21 | C29: 1700 | D29: 8 | E29: 6 | F29: 10 | G29: 10 | H29: 200 | I29: 30 | J29: 75 | L29: 3.01 | M29: 2.83 | N29: =C29*$C$4+D29*$D$4+E29*$E$4+F29*$F$4+G29*$G$4+H29*$H$4+I29*$I$4+J29*$J$4 -> 6075 | O29: =L29*$L$4+M29*$M$4 -> 10.085 | P29: 5476 | Q29: =P29*7 -> 38332 | R29: =N29*$N$4 -> 6075 | S29: =O29*$O$4 -> 10085 | T29: =Q29*$Q$4 -> 7666.4 | U29: =SUM(R29:T29) -> 23826.4 | V29: =RANK(R29,$R$9:$R$10002) -> 37 | W29: =RANK(S29,$S$9:$S$10002) -> 9 | X29: =RANK(T29,$T$9:$T$10002) -> 11 | Y29: =RANK(U29,$U$9:$U$10002) -> 9 | Z29: =_xlfn.CONCAT(ROUND((1-PERCENTRANK($U$9:$U$10002,U29,2))*100,2),"%") -> 14%
A30: 45690 | B30: 22 | C30: 0 | D30: 7 | E30: 10 | F30: 20 | G30: 15 | H30: 0 | I30: 8 | J30: 75 | L30: 0 | M30: 0 | N30: =C30*$C$4+D30*$D$4+E30*$E$4+F30*$F$4+G30*$G$4+H30*$H$4+I30*$I$4+J30*$J$4 -> 3155 | O30: =L30*$L$4+M30*$M$4 -> 0 | P30: 9634 | Q30: =P30*7 -> 67438 | R30: =N30*$N$4 -> 3155 | S30: =O30*$O$4 -> 0 | T30: =Q30*$Q$4 -> 13487.6 | U30: =SUM(R30:T30) -> 16642.6 | V30: =RANK(R30,$R$9:$R$10002) -> 56 | W30: =RANK(S30,$S$9:$S$10002) -> 59 | X30: =RANK(T30,$T$9:$T$10002) -> 1 | Y30: =RANK(U30,$U$9:$U$10002) -> 46 | Z30: =_xlfn.CONCAT(ROUND((1-PERCENTRANK($U$9:$U$10002,U30,2))*100,2),"%") -> 78%
A31: 45697 | B31: 23 | C31: 1200 | D31: 13 | E31: 12 | F31: 40 | G31: 40 | H31: 200 | I31: 40 | J31: 75 | L31: 1.71 | M31: 1.1 | N31: =C31*$C$4+D31*$D$4+E31*$E$4+F31*$F$4+G31*$G$4+H31*$H$4+I31*$I$4+J31*$J$4 -> 9295 | O31: =L31*$L$4+M31*$M$4 -> 4.46 | P31: 6345 | Q31: =P31*7 -> 44415 | R31: =N31*$N$4 -> 9295 | S31: =O31*$O$4 -> 4460 | T31: =Q31*$Q$4 -> 8883 | U31: =SUM(R31:T31) -> 22638 | V31: =RANK(R31,$R$9:$R$10002) -> 12 | W31: =RANK(S31,$S$9:$S$10002) -> 50 | X31: =RANK(T31,$T$9:$T$10002) -> 6 | Y31: =RANK(U31,$U$9:$U$10002) -> 16 | Z31: =_xlfn.CONCAT(ROUND((1-PERCENTRANK($U$9:$U$10002,U31,2))*100,2),"%") -> 26%
A32: 45704 | B32: 24 | C32: 2400 | D32: 11 | E32: 5 | F32: 20 | G32: 10 | H32: 100 | I32: 20 | J32: 75 | L32: 1.69 | M32: 1.2 | N32: =C32*$C$4+D32*$D$4+E32*$E$4+F32*$F$4+G32*$G$4+H32*$H$4+I32*$I$4+J32*$J$4 -> 6360 | O32: =L32*$L$4+M32*$M$4 -> 4.69 | P32: 4803 | Q32: =P32*7 -> 33621 | R32: =N32*$N$4 -> 6360 | S32: =O32*$O$4 -> 4690 | T32: =Q32*$Q$4 -> 6724.2 | U32: =SUM(R32:T32) -> 17774.2 | V32: =RANK(R32,$R$9:$R$10002) -> 35 | W32: =RANK(S32,$S$9:$S$10002) -> 48 | X32: =RANK(T32,$T$9:$T$10002) -> 16 | Y32: =RANK(U32,$U$9:$U$10002) -> 40 | Z32: =_xlfn.CONCAT(ROUND((1-PERCENTRANK($U$9:$U$10002,U32,2))*100,2),"%") -> 68%
A33: 45711 | B33: 25 | C33: 376 | D33: 6 | E33: 10 | F33: 17 | G33: 17 | H33: 100 | I33: 30 | J33: 75 | L33: 1.25 | M33: 1.3 | N33: =C33*$C$4+D33*$D$4+E33*$E$4+F33*$F$4+G33*$G$4+H33*$H$4+I33*$I$4+J33*$J$4 -> 4941 | O33: =L33*$L$4+M33*$M$4 -> 4.5 | P33: 4505 | Q33: =P33*7 -> 31535 | R33: =N33*$N$4 -> 4941 | S33: =O33*$O$4 -> 4500 | T33: =Q33*$Q$4 -> 6307 | U33: =SUM(R33:T33) -> 15748 | V33: =RANK(R33,$R$9:$R$10002) -> 45 | W33: =RANK(S33,$S$9:$S$10002) -> 49 | X33: =RANK(T33,$T$9:$T$10002) -> 21 | Y33: =RANK(U33,$U$9:$U$10002) -> 53 | Z33: =_xlfn.CONCAT(ROUND((1-PERCENTRANK($U$9:$U$10002,U33,2))*100,2),"%") -> 90%
A34: 45718 | B34: 26 | C34: 3300 | D34: 19 | E34: 5 | F34: 10 | G34: 10 | H34: 0 | I34: 20 | J34: 0 | L34: 1.27 | M34: 0.79 | N34: =C34*$C$4+D34*$D$4+E34*$E$4+F34*$F$4+G34*$G$4+H34*$H$4+I34*$I$4+J34*$J$4 -> 6465 | O34: =L34*$L$4+M34*$M$4 -> 3.245 | P34: 6080 | Q34: =P34*7 -> 42560 | R34: =N34*$N$4 -> 6465 | S34: =O34*$O$4 -> 3245 | T34: =Q34*$Q$4 -> 8512 | U34: =SUM(R34:T34) -> 18222 | V34: =RANK(R34,$R$9:$R$10002) -> 34 | W34: =RANK(S34,$S$9:$S$10002) -> 53 | X34: =RANK(T34,$T$9:$T$10002) -> 8 | Y34: =RANK(U34,$U$9:$U$10002) -> 38 | Z34: =_xlfn.CONCAT(ROUND((1-PERCENTRANK($U$9:$U$10002,U34,2))*100,2),"%") -> 64%
A35: 45725 | B35: 27 | C35: 618 | D35: 5 | E35: 5 | F35: 10 | G35: 10 | H35: 100 | I35: 10 | J35: 75 | K35: 40 | L35: 4.03 | M35: 0.88 | N35: =C35*$C$4+D35*$D$4+E35*$E$4+F35*$F$4+G35*$G$4+H35*$H$4+I35*$I$4+J35*$J$4+$K$4*K35 -> 3568 | O35: =L35*$L$4+M35*$M$4 -> 6.23 | P35: 3634 | Q35: =P35*7 -> 25438 | R35: =N35*$N$4 -> 3568 | S35: =O35*$O$4 -> 6230 | T35: =Q35*$Q$4 -> 5087.6 | U35: =SUM(R35:T35) -> 14885.6 | V35: =RANK(R35,$R$9:$R$10002) -> 54 | W35: =RANK(S35,$S$9:$S$10002) -> 30 | X35: =RANK(T35,$T$9:$T$10002) -> 39 | Y35: =RANK(U35,$U$9:$U$10002) -> 54 | Z35: =_xlfn.CONCAT(ROUND((1-PERCENTRANK($U$9:$U$10002,U35,2))*100,2),"%") -> 92%
A36: 45732 | B36: 28 | C36: 2580 | D36: 13 | E36: 11 | F36: 20 | G36: 30 | H36: 100 | I36: 27 | J36: 155 | K36: 340 | L36: 3.92 | M36: 0 | N36: =C36*$C$4+D36*$D$4+E36*$E$4+F36*$F$4+G36*$G$4+H36*$H$4+I36*$I$4+J36*$J$4+$K$4*K36 -> 10345 | O36: =L36*$L$4+M36*$M$4 -> 3.92 | P36: 3713 | Q36: =P36*7 -> 25991 | R36: =N36*$N$4 -> 10345 | S36: =O36*$O$4 -> 3920 | T36: =Q36*$Q$4 -> 5198.2 | U36: =SUM(R36:T36) -> 19463.2 | V36: =RANK(R36,$R$9:$R$10002) -> 5 | W36: =RANK(S36,$S$9:$S$10002) -> 52 | X36: =RANK(T36,$T$9:$T$10002) -> 36 | Y36: =RANK(U36,$U$9:$U$10002) -> 29 | Z36: =_xlfn.CONCAT(ROUND((1-PERCENTRANK($U$9:$U$10002,U36,2))*100,2),"%") -> 49%
A37: 45739 | B37: 29 | C37: =479+2320 -> 2799 | D37: 9 | E37: 7 | F37: 20 | G37: 20 | H37: 50 | I37: 10 | J37: 100 | K37: 180 | L37: 3.06 | M37: 1 | N37: =C37*$C$4+D37*$D$4+E37*$E$4+F37*$F$4+G37*$G$4+H37*$H$4+I37*$I$4+J37*$J$4+$K$4*K37 -> 7554 | O37: =L37*$L$4+M37*$M$4 -> 5.56 | P37: 4524 | Q37: =P37*7 -> 31668 | R37: =N37*$N$4 -> 7554 | S37: =O37*$O$4 -> 5560 | T37: =Q37*$Q$4 -> 6333.6 | U37: =SUM(R37:T37) -> 19447.6 | V37: =RANK(R37,$R$9:$R$10002) -> 25 | W37: =RANK(S37,$S$9:$S$10002) -> 36 | X37: =RANK(T37,$T$9:$T$10002) -> 20 | Y37: =RANK(U37,$U$9:$U$10002) -> 30 | Z37: =_xlfn.CONCAT(ROUND((1-PERCENTRANK($U$9:$U$10002,U37,2))*100,2),"%") -> 50%
A38: 45746 | B38: 30 | C38: =318+1362 -> 1680 | D38: 0 | E38: 0 | F38: 23 | G38: 15 | H38: 100 | I38: 10 | J38: 80 | K38: 160 | L38: 2.99 | M38: 0.86 | N38: =C38*$C$4+D38*$D$4+E38*$E$4+F38*$F$4+G38*$G$4+H38*$H$4+I38*$I$4+J38*$J$4+$K$4*K38 -> 5500 | O38: =L38*$L$4+M38*$M$4 -> 5.14 | P38: 5443 | Q38: =P38*7 -> 38101 | R38: =N38*$N$4 -> 5500 | S38: =O38*$O$4 -> 5140 | T38: =Q38*$Q$4 -> 7620.2 | U38: =SUM(R38:T38) -> 18260.2 | V38: =RANK(R38,$R$9:$R$10002) -> 38 | W38: =RANK(S38,$S$9:$S$10002) -> 45 | X38: =RANK(T38,$T$9:$T$10002) -> 12 | Y38: =RANK(U38,$U$9:$U$10002) -> 37 | Z38: =_xlfn.CONCAT(ROUND((1-PERCENTRANK($U$9:$U$10002,U38,2))*100,2),"%") -> 63%
A39: 45753 | B39: 31 | C39: =467+2120 -> 2587 | D39: 13 | E39: 10 | F39: 27 | G39: 15 | H39: 150 | I39: 20 | J39: 80 | K39: 180 | L39: 2.99 | M39: 0.81 | N39: =C39*$C$4+D39*$D$4+E39*$E$4+F39*$F$4+G39*$G$4+H39*$H$4+I39*$I$4+J39*$J$4+$K$4*K39 -> 8597 | O39: =L39*$L$4+M39*$M$4 -> 5.015 | P39: 2770 | Q39: =P39*7 -> 19390 | R39: =N39*$N$4 -> 8597 | S39: =O39*$O$4 -> 5015 | T39: =Q39*$Q$4 -> 3878 | U39: =SUM(R39:T39) -> 17490 | V39: =RANK(R39,$R$9:$R$10002) -> 15 | W39: =RANK(S39,$S$9:$S$10002) -> 46 | X39: =RANK(T39,$T$9:$T$10002) -> 52 | Y39: =RANK(U39,$U$9:$U$10002) -> 42 | Z39: =_xlfn.CONCAT(ROUND((1-PERCENTRANK($U$9:$U$10002,U39,2))*100,2),"%") -> 71%
A40: 45760 | B40: 32 | C40: 0 | D40: 18 | E40: 5 | F40: 10 | G40: 5 | H40: 100 | I40: 13 | J40: 0 | K40: 0 | L40: 4.32 | M40: 2 | N40: =C40*$C$4+D40*$D$4+E40*$E$4+F40*$F$4+G40*$G$4+H40*$H$4+I40*$I$4+J40*$J$4+$K$4*K40 -> 3040 | O40: =L40*$L$4+M40*$M$4 -> 9.32 | P40: 3552 | Q40: =P40*7 -> 24864 | R40: =N40*$N$4 -> 3040 | S40: =O40*$O$4 -> 9320 | T40: =Q40*$Q$4 -> 4972.8 | U40: =SUM(R40:T40) -> 17332.8 | V40: =RANK(R40,$R$9:$R$10002) -> 58 | W40: =RANK(S40,$S$9:$S$10002) -> 16 | X40: =RANK(T40,$T$9:$T$10002) -> 41 | Y40: =RANK(U40,$U$9:$U$10002) -> 44 | Z40: =_xlfn.CONCAT(ROUND((1-PERCENTRANK($U$9:$U$10002,U40,2))*100,2),"%") -> 75%
A41: 45767 | B41: 33 | C41: 2490 | D41: 11 | E41: 10 | F41: 23 | G41: 13 | H41: 150 | I41: 22 | J41: 100 | K41: 100 | L41: 4.77 | M41: 1.2 | N41: =C41*$C$4+D41*$D$4+E41*$E$4+F41*$F$4+G41*$G$4+H41*$H$4+I41*$I$4+J41*$J$4+$K$4*K41 -> 7910 | O41: =L41*$L$4+M41*$M$4 -> 7.77 | P41: 7082 | Q41: =P41*7 -> 49574 | R41: =N41*$N$4 -> 7910 | S41: =O41*$O$4 -> 7770 | T41: =Q41*$Q$4 -> 9914.8 | U41: =SUM(R41:T41) -> 25594.8 | V41: =RANK(R41,$R$9:$R$10002) -> 22 | W41: =RANK(S41,$S$9:$S$10002) -> 21 | X41: =RANK(T41,$T$9:$T$10002) -> 3 | Y41: =RANK(U41,$U$9:$U$10002) -> 4 | Z41: =_xlfn.CONCAT(ROUND((1-PERCENTRANK($U$9:$U$10002,U41,2))*100,2),"%") -> 6%
A42: 45774 | B42: 34 | C42: =230+1050 -> 1280 | D42: 11 | E42: 10 | F42: 10 | G42: 0 | H42: 100 | I42: 20 | J42: 100 | K42: 100 | L42: 3.35 | M42: 1.07 | N42: =C42*$C$4+D42*$D$4+E42*$E$4+F42*$F$4+G42*$G$4+H42*$H$4+I42*$I$4+J42*$J$4+$K$4*K42 -> 5190 | O42: =L42*$L$4+M42*$M$4 -> 6.025 | P42: 4232 | Q42: =P42*7 -> 29624 | R42: =N42*$N$4 -> 5190 | S42: =O42*$O$4 -> 6025 | T42: =Q42*$Q$4 -> 5924.8 | U42: =SUM(R42:T42) -> 17139.8 | V42: =RANK(R42,$R$9:$R$10002) -> 43 | W42: =RANK(S42,$S$9:$S$10002) -> 31 | X42: =RANK(T42,$T$9:$T$10002) -> 29 | Y42: =RANK(U42,$U$9:$U$10002) -> 45 | Z42: =_xlfn.CONCAT(ROUND((1-PERCENTRANK($U$9:$U$10002,U42,2))*100,2),"%") -> 76%
A43: 45781 | B43: 35 | C43: =1360+720 -> 2080 | D43: 11 | E43: 10 | F43: 30 | G43: 20 | H43: 200 | I43: 22 | J43: 80 | K43: 160 | L43: 3.19 | M43: 0.84 | N43: =C43*$C$4+D43*$D$4+E43*$E$4+F43*$F$4+G43*$G$4+H43*$H$4+I43*$I$4+J43*$J$4+$K$4*K43 -> 8580 | O43: =L43*$L$4+M43*$M$4 -> 5.29 | P43: 7423 | Q43: =P43*7 -> 51961 | R43: =N43*$N$4 -> 8580 | S43: =O43*$O$4 -> 5290 | T43: =Q43*$Q$4 -> 10392.2 | U43: =SUM(R43:T43) -> 24262.2 | V43: =RANK(R43,$R$9:$R$10002) -> 16 | W43: =RANK(S43,$S$9:$S$10002) -> 42 | X43: =RANK(T43,$T$9:$T$10002) -> 2 | Y43: =RANK(U43,$U$9:$U$10002) -> 7 | Z43: =_xlfn.CONCAT(ROUND((1-PERCENTRANK($U$9:$U$10002,U43,2))*100,2),"%") -> 11%
...

Sheet 按摩基金
A1: 週數 | B1: 總評分 | C1: 兌換比值 | D1: 新增基金 | E1: 基金現額 | F1: 基金使用 | G1: 運動基金總計 | H1: =SUM($D$3:$D$10000)+E2 -> 59681 | I1: 兌換比值 | J1: 0.05
E2: 1112
A3: 1 | B3: =運動!U9 -> 19224 | C3: =$J$1 -> 0.05 | D3: =ROUND(B3*C3,0) -> 961 | E3: =E2+D3-F3 -> 2073 | F3: 0
A4: 2 | B4: =運動!U10 -> 16361.4 | C4: =$J$1 -> 0.05 | D4: =ROUND(B4*C4,0) -> 818 | E4: =E3+D4-F4 -> 2891 | F4: 0
A5: 3 | B5: =運動!U11 -> 22646.2 | C5: =$J$1 -> 0.05 | D5: =ROUND(B5*C5,0) -> 1132 | E5: =E4+D5-F5 -> 4023 | F5: 0
A6: 4 | B6: =運動!U12 -> 20920.6 | C6: =$J$1 -> 0.05 | D6: =ROUND(B6*C6,0) -> 1046 | E6: =E5+D6-F6 -> 4069 | F6: 1000
A7: 5 | B7: =運動!U13 -> 18651 | C7: =$J$1 -> 0.05 | D7: =ROUND(B7*C7,0) -> 933 | E7: =E6+D7-F7 -> 4002 | F7: 1000
A8: 6 | B8: =運動!U14 -> 16283.6 | C8: =$J$1 -> 0.05 | D8: =ROUND(B8*C8,0) -> 814 | E8: =E7+D8-F8 -> 3816 | F8: 1000
A9: 7 | B9: =運動!U15 -> 19219.4 | C9: =$J$1 -> 0.05 | D9: =ROUND(B9*C9,0) -> 961 | E9: =E8+D9-F9 -> 4777 | F9: 0
A10: 8 | B10: =運動!U16 -> 15959 | C10: =$J$1 -> 0.05 | D10: =ROUND(B10*C10,0) -> 798 | E10: =E9+D10-F10 -> 4575 | F10: 1000
A11: 9 | B11: =運動!U17 -> 17441.8 | C11: =$J$1 -> 0.05 | D11: =ROUND(B11*C11,0) -> 872 | E11: =E10+D11-F11 -> 5447 | F11: 0
A12: 10 | B12: =運動!U18 -> 12168.4 | C12: =$J$1 -> 0.05 | D12: =ROUND(B12*C12,0) -> 608 | E12: =E11+D12-F12 -> 4055 | F12: 2000
A13: 11 | B13: =運動!U19 -> 19622.4 | C13: =$J$1 -> 0.05 | D13: =ROUND(B13*C13,0) -> 981 | E13: =E12+D13-F13 -> 2036 | F13: 3000
A14: 12 | B14: =運動!U20 -> 15860.8 | C14: =$J$1 -> 0.05 | D14: =ROUND(B14*C14,0) -> 793 | E14: =E13+D14-F14 -> 2829 | F14: 0
... A20: 18 | B20: =運動!U26 -> 25027.6 | C20: =$J$1 -> 0.05 | D20: =ROUND(B20*C20,0) -> 1251 | E20: =E19+D20-F20 -> 5359 | F20: 1000
A21: 19 | B21: =運動!U27 -> 22029.6 | C21: =$J$1 -> 0.05 | D21: =ROUND(B21*C21,0) -> 1101 | E21: =E20+D21-F21 -> 6460
A22: 20 | B22: =運動!U28 -> 27176.6 | C22: =$J$1 -> 0.05 | D22: =ROUND(B22*C22,0) -> 1359 | E22: =E21+D22-F22 -> 6819 | F22: 1000
A23: 21 | B23: =運動!U29 -> 23826.4 | C23: =$J$1 -> 0.05 | D23: =ROUND(B23*C23,0) -> 1191 | E23: =E22+D23-F23 -> 7010 | F23: 1000
A24: 22 | B24: =運動!U30 -> 16642.6 | C24: =$J$1 -> 0.05 | D24: =ROUND(B24*C24,0) -> 832 | E24: =E23+D24-F24 -> 6842 | F24: 1000
A25: 23 | B25: =運動!U31 -> 22638 | C25: =$J$1 -> 0.05 | D25: =ROUND(B25*C25,0) -> 1132 | E25: =E24+D25-F25 -> 7974 | F25: 0
A26: 24 | B26: =運動!U32 -> 17774.2 | C26: =$J$1 -> 0.05 | D26: =ROUND(B26*C26,0) -> 889 | E26: =E25+D26-F26 -> 8863 | F26: 0
A27: 25 | B27: =運動!U33 -> 15748 | C27: =$J$1 -> 0.05 | D27: =ROUND(B27*C27,0) -> 787 | E27: =E26+D27-F27 -> 9650 | F27: 0
A28: 26 | B28: =運動!U34 -> 18222 | C28: =$J$1 -> 0.05 | D28: =ROUND(B28*C28,0) -> 911 | E28: =E27+D28-F28 -> 8561 | F28: 2000
A29: 27 | B29: =運動!U35 -> 14885.6 | C29: =$J$1 -> 0.05 | D29: =ROUND(B29*C29,0) -> 744 | E29: =E28+D29-F29 -> 7305 | F29: 2000
A30: 28 | B30: =運動!U36 -> 19463.2 | C30: =$J$1 -> 0.05 | D30: =ROUND(B30*C30,0) -> 973 | E30: =E29+D30-F30 -> 4278 | F30: 4000
A31: 29 | B31: =運動!U37 -> 19447.6 | C31: =$J$1 -> 0.05 | D31: =ROUND(B31*C31,0) -> 972 | E31: =E30+D31-F31 -> 4250 | F31: 1000
A32: 30 | B32: =運動!U38 -> 18260.2 | C32: =$J$1 -> 0.05 | D32: =ROUND(B32*C32,0) -> 913 | E32: =E31+D32-F32 -> 5163 | F32: 0
A33: 31 | B33: =運動!U39 -> 17490 | C33: =$J$1 -> 0.05 | D33: =ROUND(B33*C33,0) -> 875 | E33: =E32+D33-F33 -> 6038 | F33: 0
... A49: 47 | B49: =運動!U55 -> 18482 | C49: =$J$1 -> 0.05 | D49: =ROUND(B49*C49,0) -> 924 | E49: =E48+D49-F49 -> 5311 | F49: 0
A50: 48 | B50: =運動!U56 -> 23420.8 | C50: =$J$1 -> 0.05 | D50: =ROUND(B50*C50,0) -> 1171 | E50: =E49+D50-F50 -> 6482
A51: 49 | B51: =運動!U57 -> 12788.6 | C51: =$J$1 -> 0.05 | D51: =ROUND(B51*C51,0) -> 639 | E51: =E50+D51-F51 -> 7121
A52: 50 | B52: =運動!U58 -> 21506 | C52: =$J$1 -> 0.05 | D52: =ROUND(B52*C52,0) -> 1075 | E52: =E51+D52-F52 -> 6696 | F52: 1500
A53: 51 | B53: =運動!U59 -> 23698.6 | C53: =$J$1 -> 0.05 | D53: =ROUND(B53*C53,0) -> 1185 | E53: =E52+D53-F53 -> 7881
A54: 52 | B54: =運動!U60 -> 18751.4 | C54: =$J$1 -> 0.05 | D54: =ROUND(B54*C54,0) -> 938 | E54: =E53+D54-F54 -> 6819 | F54: 2000
A55: 53 | B55: =運動!U61 -> 23773 | C55: =$J$1 -> 0.05 | D55: =ROUND(B55*C55,0) -> 1189 | E55: =E54+D55-F55 -> 6008 | F55: 2000
A56: 54 | B56: =運動!U62 -> 20574.8 | C56: =$J$1 -> 0.05 | D56: =ROUND(B56*C56,0) -> 1029 | E56: =E55+D56-F56 -> 3537 | F56: 3500
A57: 55 | B57: =運動!U63 -> 31639.4 | C57: =$J$1 -> 0.05 | D57: =ROUND(B57*C57,0) -> 1582 | E57: =E56+D57-F57 -> 5119
A58: 56 | B58: =運動!U64 -> 23365.4 | C58: =$J$1 -> 0.05 | D58: =ROUND(B58*C58,0) -> 1168 | E58: =E57+D58-F58 -> 4787 | F58: 1500
A59: 57 | B59: =運動!U65 -> 30590.4 | C59: =$J$1 -> 0.05 | D59: =ROUND(B59*C59,0) -> 1530 | E59: =E58+D59-F59 -> 6317
A60: 58 | B60: =運動!U66 -> 22982.8 | C60: =$J$1 -> 0.05 | D60: =ROUND(B60*C60,0) -> 1149 | E60: =E59+D60-F60 -> 7466 | F60: 0
...

Sheet 趨勢
